<sdf version='1.6'>
  <world name='default'>
    <light name='sun' type='directional'>
      <cast_shadows>1</cast_shadows>
      <pose frame=''>0 0 10 0 -0 0</pose>
      <diffuse>0.8 0.8 0.8 1</diffuse>
      <specular>0.2 0.2 0.2 1</specular>
      <attenuation>
        <range>1000</range>
        <constant>0.9</constant>
        <linear>0.01</linear>
        <quadratic>0.001</quadratic>
      </attenuation>
      <direction>-0.5 0.1 -0.9</direction>
    </light>
    <gravity>0 0 -9.8</gravity>
    <magnetic_field>6e-06 2.3e-05 -4.2e-05</magnetic_field>
    <atmosphere type='adiabatic'/>
    <physics name='default_physics' default='0' type='ode'>
      <max_step_size>0.001</max_step_size>
      <real_time_factor>1</real_time_factor>
      <real_time_update_rate>1000</real_time_update_rate>
    </physics>
    <scene>
      <ambient>0.4 0.4 0.4 1</ambient>
      <background>0.7 0.7 0.7 1</background>
      <shadows>1</shadows>
    </scene>
    <spherical_coordinates>
      <surface_model>EARTH_WGS84</surface_model>
      <latitude_deg>0</latitude_deg>
      <longitude_deg>0</longitude_deg>
      <elevation>0</elevation>
      <heading_deg>0</heading_deg>
    </spherical_coordinates>
    <model name='allegro_right_hand'>
      <link name='palm_link'>
        <pose frame=''>0 0 0.095 0 -0 0</pose>
        <inertial>
          <pose frame=''>0 0 0.0475 0 -0 0</pose>
          <mass>0.4154</mass>
          <inertia>
            <ixx>0.001</ixx>
            <ixy>0.001</ixy>
            <ixz>0.001</ixz>
            <iyy>0.001</iyy>
            <iyz>0.001</iyz>
            <izz>0.001</izz>
          </inertia>
        </inertial>
        <collision name='palm_link_collision'>
          <pose frame=''>-0.0093 0 -0.0475 0 -0 0</pose>
          <geometry>
            <box>
              <size>0.0408 0.113 0.095</size>
            </box>
          </geometry>
          <max_contacts>10</max_contacts>
          <surface>
            <contact>
              <ode/>
            </contact>
            <bounce/>
            <friction>
              <torsional>
                <ode/>
              </torsional>
              <ode/>
            </friction>
          </surface>
        </collision>
        <visual name='palm_link_visual'>
          <pose frame=''>0 0 0 0 -0 0</pose>
          <geometry>
            <mesh>
              <scale>1 1 1</scale>
              <uri>/home/work/code_repository/ros_packages/src/allegro_right_hand_description/model/meshes/base_link.STL</uri>
            </mesh>
          </geometry>
        </visual>
        <self_collide>0</self_collide>
        <kinematic>0</kinematic>
      </link>
      <joint name='fix_to_world' type='fixed'>
        <child>palm_link</child>
        <parent>world</parent>
      </joint>
      <link name='index_link0'>
        <pose frame=''>0 0.0435 0.093458 -0.087267 0 0</pose>
        <inertial>
          <pose frame=''>0 0 0 0 -0 0</pose>
          <mass>0.119</mass>
          <inertia>
            <ixx>0.001</ixx>
            <ixy>0.001</ixy>
            <ixz>0.001</ixz>
            <iyy>0.001</iyy>
            <iyz>0.001</iyz>
            <izz>0.001</izz>
          </inertia>
        </inertial>
        <collision name='index_link0_collision'>
          <pose frame=''>0 0 0.0082 0 -0 0</pose>
          <geometry>
            <box>
              <size>0.0196 0.0275 0.0164</size>
            </box>
          </geometry>
          <surface>
            <contact>
              <ode/>
            </contact>
            <friction>
              <ode/>
              <torsional>
                <ode/>
              </torsional>
            </friction>
            <bounce/>
          </surface>
          <max_contacts>10</max_contacts>
        </collision>
        <visual name='index_link0_visual'>
          <pose frame=''>0 0 0 0 -0 0</pose>
          <geometry>
            <mesh>
              <scale>1 1 1</scale>
              <uri>/home/work/code_repository/ros_packages/src/allegro_right_hand_description/model/meshes/link_0.0.STL</uri>
            </mesh>
          </geometry>
          <material>
            <script>
              <name>Gazebo/Blue</name>
              <uri>file://media/materials/scripts/gazebo.material</uri>
            </script>
          </material>
        </visual>
        <gravity>1</gravity>
        <velocity_decay/>
        <self_collide>0</self_collide>
        <kinematic>0</kinematic>
      </link>
      <joint name='index_joint1' type='revolute'>
        <child>index_link0</child>
        <parent>palm_link</parent>
        <axis>
          <xyz>0 0.087156 0.996195</xyz>
          <limit>
            <lower>-0.47</lower>
            <upper>0.47</upper>
            <effort>15</effort>
            <velocity>7</velocity>
          </limit>
          <dynamics>
            <damping>1</damping>
            <friction>1</friction>
            <spring_reference>0</spring_reference>
            <spring_stiffness>0</spring_stiffness>
          </dynamics>
          <use_parent_model_frame>1</use_parent_model_frame>
        </axis>
      </joint>
      <link name='index_link1'>
        <pose frame=''>0 0.044929 0.109796 -0.087267 0 0</pose>
        <inertial>
          <pose frame=''>0 0 0 0 -0 0</pose>
          <mass>0.2</mass>
          <inertia>
            <ixx>0.001</ixx>
            <ixy>0.001</ixy>
            <ixz>0.001</ixz>
            <iyy>0.001</iyy>
            <iyz>0.001</iyz>
            <izz>0.001</izz>
          </inertia>
        </inertial>
        <collision name='index_link1_collision'>
          <pose frame=''>0 0 0.027 0 -0 0</pose>
          <geometry>
            <box>
              <size>0.0196 0.0275 0.054</size>
            </box>
          </geometry>
          <surface>
            <contact>
              <ode/>
            </contact>
            <friction>
              <ode/>
              <torsional>
                <ode/>
              </torsional>
            </friction>
            <bounce/>
          </surface>
          <max_contacts>10</max_contacts>
        </collision>
        <visual name='index_link1_visual'>
          <pose frame=''>0 0 0 0 -0 0</pose>
          <geometry>
            <mesh>
              <scale>1 1 1</scale>
              <uri>/home/work/code_repository/ros_packages/src/allegro_right_hand_description/model/meshes/link_1.0.STL</uri>
            </mesh>
          </geometry>
          <material>
            <script>
              <name>Gazebo/Orange</name>
              <uri>file://media/materials/scripts/gazebo.material</uri>
            </script>
          </material>
        </visual>
        <gravity>1</gravity>
        <velocity_decay/>
        <self_collide>0</self_collide>
        <kinematic>0</kinematic>
      </link>
      <joint name='index_joint2' type='revolute'>
        <child>index_link1</child>
        <parent>index_link0</parent>
        <axis>
          <xyz>0 0.996195 -0.087156</xyz>
          <limit>
            <lower>-0.196</lower>
            <upper>1.61</upper>
            <effort>15</effort>
            <velocity>7</velocity>
          </limit>
          <dynamics>
            <damping>1</damping>
            <friction>1</friction>
            <spring_reference>0</spring_reference>
            <spring_stiffness>0</spring_stiffness>
          </dynamics>
          <use_parent_model_frame>1</use_parent_model_frame>
        </axis>
      </joint>
      <link name='index_link2'>
        <pose frame=''>0 0.049636 0.16359 -0.087267 0 0</pose>
        <inertial>
          <pose frame=''>0 0 0 0 -0 0</pose>
          <mass>0.15</mass>
          <inertia>
            <ixx>0.001</ixx>
            <ixy>0.001</ixy>
            <ixz>0.001</ixz>
            <iyy>0.001</iyy>
            <iyz>0.001</iyz>
            <izz>0.001</izz>
          </inertia>
        </inertial>
        <collision name='index_link2_collision'>
          <pose frame=''>0 0 0.0192 0 -0 0</pose>
          <geometry>
            <box>
              <size>0.0196 0.0275 0.0384</size>
            </box>
          </geometry>
          <surface>
            <contact>
              <ode/>
            </contact>
            <friction>
              <ode/>
              <torsional>
                <ode/>
              </torsional>
            </friction>
            <bounce/>
          </surface>
          <max_contacts>10</max_contacts>
        </collision>
        <visual name='index_link2_visual'>
          <pose frame=''>0 0 0 0 -0 0</pose>
          <geometry>
            <mesh>
              <scale>1 1 1</scale>
              <uri>/home/work/code_repository/ros_packages/src/allegro_right_hand_description/model/meshes/link_2.0.STL</uri>
            </mesh>
          </geometry>
          <material>
            <script>
              <name>Gazebo/Red</name>
              <uri>file://media/materials/scripts/gazebo.material</uri>
            </script>
          </material>
        </visual>
        <gravity>1</gravity>
        <velocity_decay/>
        <self_collide>0</self_collide>
        <kinematic>0</kinematic>
      </link>
      <joint name='index_joint3' type='revolute'>
        <child>index_link2</child>
        <parent>index_link1</parent>
        <axis>
          <xyz>0 0.996195 -0.087156</xyz>
          <limit>
            <lower>-0.174</lower>
            <upper>1.709</upper>
            <effort>15</effort>
            <velocity>7</velocity>
          </limit>
          <dynamics>
            <damping>1</damping>
            <friction>1</friction>
            <spring_reference>0</spring_reference>
            <spring_stiffness>0</spring_stiffness>
          </dynamics>
          <use_parent_model_frame>1</use_parent_model_frame>
        </axis>
      </joint>
      <link name='index_link3'>
        <pose frame=''>0 0.052983 0.201844 -0.087267 0 0</pose>
        <inertial>
          <pose frame=''>0 0 0.01335 0 -0 0</pose>
          <mass>0.2</mass>
          <inertia>
            <ixx>0.00203564</ixx>
            <ixy>0.002</ixy>
            <ixz>0.002</ixz>
            <iyy>0.00203564</iyy>
            <iyz>0.002</iyz>
            <izz>0.002</izz>
          </inertia>
        </inertial>
        <collision name='index_link3_collision'>
          <pose frame=''>0 0 0.01335 0 -0 0</pose>
          <geometry>
            <box>
              <size>0.0196 0.0275 0.0267</size>
            </box>
          </geometry>
          <surface>
            <contact>
              <ode/>
            </contact>
            <friction>
              <ode/>
              <torsional>
                <ode/>
              </torsional>
            </friction>
            <bounce/>
          </surface>
          <max_contacts>10</max_contacts>
        </collision>
        <collision name='index_link3_fixed_joint_lump__index_link_tip_collision_1'>
          <pose frame=''>0 0 0.0267 0 -0 0</pose>
          <geometry>
            <sphere>
              <radius>0.012</radius>
            </sphere>
          </geometry>
          <surface>
            <contact>
              <ode/>
            </contact>
            <friction>
              <ode/>
              <torsional>
                <ode/>
              </torsional>
            </friction>
            <bounce/>
          </surface>
          <max_contacts>10</max_contacts>
        </collision>
        <visual name='index_link3_visual'>
          <pose frame=''>0 0 0 0 -0 0</pose>
          <geometry>
            <mesh>
              <scale>1 1 1</scale>
              <uri>/home/work/code_repository/ros_packages/src/allegro_right_hand_description/model/meshes/link_3.0.STL</uri>
            </mesh>
          </geometry>
          <material>
            <script>
              <name>Gazebo/White</name>
              <uri>file://media/materials/scripts/gazebo.material</uri>
            </script>
          </material>
        </visual>
        <visual name='index_link3_fixed_joint_lump__index_link_tip_visual_1'>
          <pose frame=''>0 0 0.0267 0 -0 0</pose>
          <geometry>
            <mesh>
              <scale>1 1 1</scale>
              <uri>/home/work/code_repository/ros_packages/src/allegro_right_hand_description/model/meshes/link_3.0_tip.STL</uri>
            </mesh>
          </geometry>
          <material>
            <script>
              <name>Gazebo/White</name>
              <uri>file://media/materials/scripts/gazebo.material</uri>
            </script>
          </material>
        </visual>
        <velocity_decay/>
        <gravity>1</gravity>
        <velocity_decay/>
        <self_collide>0</self_collide>
        <kinematic>0</kinematic>
      </link>
      <joint name='index_joint4' type='revolute'>
        <child>index_link3</child>
        <parent>index_link2</parent>
        <axis>
          <xyz>0 0.996195 -0.087156</xyz>
          <limit>
            <lower>-0.227</lower>
            <upper>1.618</upper>
            <effort>15</effort>
            <velocity>7</velocity>
          </limit>
          <dynamics>
            <damping>1</damping>
            <friction>1</friction>
            <spring_reference>0</spring_reference>
            <spring_stiffness>0</spring_stiffness>
          </dynamics>
          <use_parent_model_frame>1</use_parent_model_frame>
        </axis>
      </joint>
      <link name='middle_link0'>
        <pose frame=''>0 0 0.0957 0 -0 0</pose>
        <inertial>
          <pose frame=''>0 0 0 0 -0 0</pose>
          <mass>0.119</mass>
          <inertia>
            <ixx>0.001</ixx>
            <ixy>0.001</ixy>
            <ixz>0.001</ixz>
            <iyy>0.001</iyy>
            <iyz>0.001</iyz>
            <izz>0.001</izz>
          </inertia>
        </inertial>
        <collision name='middle_link0_collision'>
          <pose frame=''>0 0 0.0082 0 -0 0</pose>
          <geometry>
            <box>
              <size>0.0196 0.0275 0.0164</size>
            </box>
          </geometry>
          <surface>
            <contact>
              <ode/>
            </contact>
            <friction>
              <ode/>
              <torsional>
                <ode/>
              </torsional>
            </friction>
            <bounce/>
          </surface>
          <max_contacts>10</max_contacts>
        </collision>
        <visual name='middle_link0_visual'>
          <pose frame=''>0 0 0 0 -0 0</pose>
          <geometry>
            <mesh>
              <scale>1 1 1</scale>
              <uri>/home/work/code_repository/ros_packages/src/allegro_right_hand_description/model/meshes/link_0.0.STL</uri>
            </mesh>
          </geometry>
          <material>
            <script>
              <name>Gazebo/Blue</name>
              <uri>file://media/materials/scripts/gazebo.material</uri>
            </script>
          </material>
        </visual>
        <gravity>1</gravity>
        <velocity_decay/>
        <self_collide>0</self_collide>
        <kinematic>0</kinematic>
      </link>
      <joint name='middle_joint1' type='revolute'>
        <child>middle_link0</child>
        <parent>palm_link</parent>
        <axis>
          <xyz>0 0 1</xyz>
          <limit>
            <lower>-0.47</lower>
            <upper>0.47</upper>
            <effort>15</effort>
            <velocity>7</velocity>
          </limit>
          <dynamics>
            <damping>1</damping>
            <friction>1</friction>
            <spring_reference>0</spring_reference>
            <spring_stiffness>0</spring_stiffness>
          </dynamics>
          <use_parent_model_frame>1</use_parent_model_frame>
        </axis>
      </joint>
      <link name='middle_link1'>
        <pose frame=''>0 0 0.1121 0 -0 0</pose>
        <inertial>
          <pose frame=''>0 0 0 0 -0 0</pose>
          <mass>0.2</mass>
          <inertia>
            <ixx>0.001</ixx>
            <ixy>0.001</ixy>
            <ixz>0.001</ixz>
            <iyy>0.001</iyy>
            <iyz>0.001</iyz>
            <izz>0.001</izz>
          </inertia>
        </inertial>
        <collision name='middle_link1_collision'>
          <pose frame=''>0 0 0.027 0 -0 0</pose>
          <geometry>
            <box>
              <size>0.0196 0.0275 0.054</size>
            </box>
          </geometry>
          <surface>
            <contact>
              <ode/>
            </contact>
            <friction>
              <ode/>
              <torsional>
                <ode/>
              </torsional>
            </friction>
            <bounce/>
          </surface>
          <max_contacts>10</max_contacts>
        </collision>
        <visual name='middle_link1_visual'>
          <pose frame=''>0 0 0 0 -0 0</pose>
          <geometry>
            <mesh>
              <scale>1 1 1</scale>
              <uri>/home/work/code_repository/ros_packages/src/allegro_right_hand_description/model/meshes/link_1.0.STL</uri>
            </mesh>
          </geometry>
          <material>
            <script>
              <name>Gazebo/Orange</name>
              <uri>file://media/materials/scripts/gazebo.material</uri>
            </script>
          </material>
        </visual>
        <gravity>1</gravity>
        <velocity_decay/>
        <self_collide>0</self_collide>
        <kinematic>0</kinematic>
      </link>
      <joint name='middle_joint2' type='revolute'>
        <child>middle_link1</child>
        <parent>middle_link0</parent>
        <axis>
          <xyz>0 1 0</xyz>
          <limit>
            <lower>-0.196</lower>
            <upper>1.61</upper>
            <effort>15</effort>
            <velocity>7</velocity>
          </limit>
          <dynamics>
            <damping>1</damping>
            <friction>1</friction>
            <spring_reference>0</spring_reference>
            <spring_stiffness>0</spring_stiffness>
          </dynamics>
          <use_parent_model_frame>1</use_parent_model_frame>
        </axis>
      </joint>
      <link name='middle_link2'>
        <pose frame=''>0 0 0.1661 0 -0 0</pose>
        <inertial>
          <pose frame=''>0 0 0 0 -0 0</pose>
          <mass>0.15</mass>
          <inertia>
            <ixx>0.001</ixx>
            <ixy>0.001</ixy>
            <ixz>0.001</ixz>
            <iyy>0.001</iyy>
            <iyz>0.001</iyz>
            <izz>0.001</izz>
          </inertia>
        </inertial>
        <collision name='middle_link2_collision'>
          <pose frame=''>0 0 0.0192 0 -0 0</pose>
          <geometry>
            <box>
              <size>0.0196 0.0275 0.0384</size>
            </box>
          </geometry>
          <surface>
            <contact>
              <ode/>
            </contact>
            <friction>
              <ode/>
              <torsional>
                <ode/>
              </torsional>
            </friction>
            <bounce/>
          </surface>
          <max_contacts>10</max_contacts>
        </collision>
        <visual name='middle_link2_visual'>
          <pose frame=''>0 0 0 0 -0 0</pose>
          <geometry>
            <mesh>
              <scale>1 1 1</scale>
              <uri>/home/work/code_repository/ros_packages/src/allegro_right_hand_description/model/meshes/link_2.0.STL</uri>
            </mesh>
          </geometry>
          <material>
            <script>
              <name>Gazebo/Red</name>
              <uri>file://media/materials/scripts/gazebo.material</uri>
            </script>
          </material>
        </visual>
        <gravity>1</gravity>
        <velocity_decay/>
        <self_collide>0</self_collide>
        <kinematic>0</kinematic>
      </link>
      <joint name='middle_joint3' type='revolute'>
        <child>middle_link2</child>
        <parent>middle_link1</parent>
        <axis>
          <xyz>0 1 0</xyz>
          <limit>
            <lower>-0.174</lower>
            <upper>1.709</upper>
            <effort>15</effort>
            <velocity>7</velocity>
          </limit>
          <dynamics>
            <damping>1</damping>
            <friction>1</friction>
            <spring_reference>0</spring_reference>
            <spring_stiffness>0</spring_stiffness>
          </dynamics>
          <use_parent_model_frame>1</use_parent_model_frame>
        </axis>
      </joint>
      <link name='middle_link3'>
        <pose frame=''>0 0 0.2045 0 -0 0</pose>
        <inertial>
          <pose frame=''>0 0 0.01335 0 -0 0</pose>
          <mass>0.2</mass>
          <inertia>
            <ixx>0.00203564</ixx>
            <ixy>0.002</ixy>
            <ixz>0.002</ixz>
            <iyy>0.00203564</iyy>
            <iyz>0.002</iyz>
            <izz>0.002</izz>
          </inertia>
        </inertial>
        <collision name='middle_link3_collision'>
          <pose frame=''>0 0 0.01335 0 -0 0</pose>
          <geometry>
            <box>
              <size>0.0196 0.0275 0.0267</size>
            </box>
          </geometry>
          <surface>
            <contact>
              <ode/>
            </contact>
            <friction>
              <ode/>
              <torsional>
                <ode/>
              </torsional>
            </friction>
            <bounce/>
          </surface>
          <max_contacts>10</max_contacts>
        </collision>
        <collision name='middle_link3_fixed_joint_lump__middle_link_tip_collision_1'>
          <pose frame=''>0 0 0.0267 0 -0 0</pose>
          <geometry>
            <sphere>
              <radius>0.012</radius>
            </sphere>
          </geometry>
          <surface>
            <contact>
              <ode/>
            </contact>
            <friction>
              <ode/>
              <torsional>
                <ode/>
              </torsional>
            </friction>
            <bounce/>
          </surface>
          <max_contacts>10</max_contacts>
        </collision>
        <visual name='middle_link3_visual'>
          <pose frame=''>0 0 0 0 -0 0</pose>
          <geometry>
            <mesh>
              <scale>1 1 1</scale>
              <uri>/home/work/code_repository/ros_packages/src/allegro_right_hand_description/model/meshes/link_3.0.STL</uri>
            </mesh>
          </geometry>
          <material>
            <script>
              <name>Gazebo/White</name>
              <uri>file://media/materials/scripts/gazebo.material</uri>
            </script>
          </material>
        </visual>
        <visual name='middle_link3_fixed_joint_lump__middle_link_tip_visual_1'>
          <pose frame=''>0 0 0.0267 0 -0 0</pose>
          <geometry>
            <mesh>
              <scale>1 1 1</scale>
              <uri>/home/work/code_repository/ros_packages/src/allegro_right_hand_description/model/meshes/link_3.0_tip.STL</uri>
            </mesh>
          </geometry>
          <material>
            <script>
              <name>Gazebo/White</name>
              <uri>file://media/materials/scripts/gazebo.material</uri>
            </script>
          </material>
        </visual>
        <velocity_decay/>
        <gravity>1</gravity>
        <velocity_decay/>
        <self_collide>0</self_collide>
        <kinematic>0</kinematic>
      </link>
      <joint name='middle_joint4' type='revolute'>
        <child>middle_link3</child>
        <parent>middle_link2</parent>
        <axis>
          <xyz>0 1 0</xyz>
          <limit>
            <lower>-0.227</lower>
            <upper>1.618</upper>
            <effort>15</effort>
            <velocity>7</velocity>
          </limit>
          <dynamics>
            <damping>1</damping>
            <friction>1</friction>
            <spring_reference>0</spring_reference>
            <spring_stiffness>0</spring_stiffness>
          </dynamics>
          <use_parent_model_frame>1</use_parent_model_frame>
        </axis>
      </joint>
      <link name='pinky_link0'>
        <pose frame=''>0 -0.0435 0.093458 0.087267 -0 0</pose>
        <inertial>
          <pose frame=''>0 0 0 0 -0 0</pose>
          <mass>0.119</mass>
          <inertia>
            <ixx>0.001</ixx>
            <ixy>0.001</ixy>
            <ixz>0.001</ixz>
            <iyy>0.001</iyy>
            <iyz>0.001</iyz>
            <izz>0.001</izz>
          </inertia>
        </inertial>
        <collision name='pinky_link0_collision'>
          <pose frame=''>0 0 0.0082 0 -0 0</pose>
          <geometry>
            <box>
              <size>0.0196 0.0275 0.0164</size>
            </box>
          </geometry>
          <surface>
            <contact>
              <ode/>
            </contact>
            <friction>
              <ode/>
              <torsional>
                <ode/>
              </torsional>
            </friction>
            <bounce/>
          </surface>
          <max_contacts>10</max_contacts>
        </collision>
        <visual name='pinky_link0_visual'>
          <pose frame=''>0 0 0 0 -0 0</pose>
          <geometry>
            <mesh>
              <scale>1 1 1</scale>
              <uri>/home/work/code_repository/ros_packages/src/allegro_right_hand_description/model/meshes/link_0.0.STL</uri>
            </mesh>
          </geometry>
          <material>
            <script>
              <name>Gazebo/Blue</name>
              <uri>file://media/materials/scripts/gazebo.material</uri>
            </script>
          </material>
        </visual>
        <gravity>1</gravity>
        <velocity_decay/>
        <self_collide>0</self_collide>
        <kinematic>0</kinematic>
      </link>
      <joint name='pinky_joint1' type='revolute'>
        <child>pinky_link0</child>
        <parent>palm_link</parent>
        <axis>
          <xyz>0 -0.087156 0.996195</xyz>
          <limit>
            <lower>-0.47</lower>
            <upper>0.47</upper>
            <effort>15</effort>
            <velocity>7</velocity>
          </limit>
          <dynamics>
            <damping>1</damping>
            <friction>1</friction>
            <spring_reference>0</spring_reference>
            <spring_stiffness>0</spring_stiffness>
          </dynamics>
          <use_parent_model_frame>1</use_parent_model_frame>
        </axis>
      </joint>
      <link name='pinky_link1'>
        <pose frame=''>0 -0.044929 0.109796 0.087267 -0 0</pose>
        <inertial>
          <pose frame=''>0 0 0 0 -0 0</pose>
          <mass>0.2</mass>
          <inertia>
            <ixx>0.001</ixx>
            <ixy>0.001</ixy>
            <ixz>0.001</ixz>
            <iyy>0.001</iyy>
            <iyz>0.001</iyz>
            <izz>0.001</izz>
          </inertia>
        </inertial>
        <collision name='pinky_link1_collision'>
          <pose frame=''>0 0 0.027 0 -0 0</pose>
          <geometry>
            <box>
              <size>0.0196 0.0275 0.054</size>
            </box>
          </geometry>
          <surface>
            <contact>
              <ode/>
            </contact>
            <friction>
              <ode/>
              <torsional>
                <ode/>
              </torsional>
            </friction>
            <bounce/>
          </surface>
          <max_contacts>10</max_contacts>
        </collision>
        <visual name='pinky_link1_visual'>
          <pose frame=''>0 0 0 0 -0 0</pose>
          <geometry>
            <mesh>
              <scale>1 1 1</scale>
              <uri>/home/work/code_repository/ros_packages/src/allegro_right_hand_description/model/meshes/link_1.0.STL</uri>
            </mesh>
          </geometry>
          <material>
            <script>
              <name>Gazebo/Orange</name>
              <uri>file://media/materials/scripts/gazebo.material</uri>
            </script>
          </material>
        </visual>
        <gravity>1</gravity>
        <velocity_decay/>
        <self_collide>0</self_collide>
        <kinematic>0</kinematic>
      </link>
      <joint name='pinky_joint2' type='revolute'>
        <child>pinky_link1</child>
        <parent>pinky_link0</parent>
        <axis>
          <xyz>0 0.996195 0.087156</xyz>
          <limit>
            <lower>-0.196</lower>
            <upper>1.61</upper>
            <effort>15</effort>
            <velocity>7</velocity>
          </limit>
          <dynamics>
            <damping>1</damping>
            <friction>1</friction>
            <spring_reference>0</spring_reference>
            <spring_stiffness>0</spring_stiffness>
          </dynamics>
          <use_parent_model_frame>1</use_parent_model_frame>
        </axis>
      </joint>
      <link name='pinky_link2'>
        <pose frame=''>0 -0.049636 0.16359 0.087267 -0 0</pose>
        <inertial>
          <pose frame=''>0 0 0 0 -0 0</pose>
          <mass>0.15</mass>
          <inertia>
            <ixx>0.001</ixx>
            <ixy>0.001</ixy>
            <ixz>0.001</ixz>
            <iyy>0.001</iyy>
            <iyz>0.001</iyz>
            <izz>0.001</izz>
          </inertia>
        </inertial>
        <collision name='pinky_link2_collision'>
          <pose frame=''>0 0 0.0192 0 -0 0</pose>
          <geometry>
            <box>
              <size>0.0196 0.0275 0.0384</size>
            </box>
          </geometry>
          <surface>
            <contact>
              <ode/>
            </contact>
            <friction>
              <ode/>
              <torsional>
                <ode/>
              </torsional>
            </friction>
            <bounce/>
          </surface>
          <max_contacts>10</max_contacts>
        </collision>
        <visual name='pinky_link2_visual'>
          <pose frame=''>0 0 0 0 -0 0</pose>
          <geometry>
            <mesh>
              <scale>1 1 1</scale>
              <uri>/home/work/code_repository/ros_packages/src/allegro_right_hand_description/model/meshes/link_2.0.STL</uri>
            </mesh>
          </geometry>
          <material>
            <script>
              <name>Gazebo/Red</name>
              <uri>file://media/materials/scripts/gazebo.material</uri>
            </script>
          </material>
        </visual>
        <gravity>1</gravity>
        <velocity_decay/>
        <self_collide>0</self_collide>
        <kinematic>0</kinematic>
      </link>
      <joint name='pinky_joint3' type='revolute'>
        <child>pinky_link2</child>
        <parent>pinky_link1</parent>
        <axis>
          <xyz>0 0.996195 0.087156</xyz>
          <limit>
            <lower>-0.174</lower>
            <upper>1.709</upper>
            <effort>15</effort>
            <velocity>7</velocity>
          </limit>
          <dynamics>
            <damping>1</damping>
            <friction>1</friction>
            <spring_reference>0</spring_reference>
            <spring_stiffness>0</spring_stiffness>
          </dynamics>
          <use_parent_model_frame>1</use_parent_model_frame>
        </axis>
      </joint>
      <link name='pinky_link3'>
        <pose frame=''>0 -0.052983 0.201844 0.087267 -0 0</pose>
        <inertial>
          <pose frame=''>0 0 0.01335 0 -0 0</pose>
          <mass>0.2</mass>
          <inertia>
            <ixx>0.00203564</ixx>
            <ixy>0.002</ixy>
            <ixz>0.002</ixz>
            <iyy>0.00203564</iyy>
            <iyz>0.002</iyz>
            <izz>0.002</izz>
          </inertia>
        </inertial>
        <collision name='pinky_link3_collision'>
          <pose frame=''>0 0 0.01335 0 -0 0</pose>
          <geometry>
            <box>
              <size>0.0196 0.0275 0.0267</size>
            </box>
          </geometry>
          <surface>
            <contact>
              <ode/>
            </contact>
            <friction>
              <ode/>
              <torsional>
                <ode/>
              </torsional>
            </friction>
            <bounce/>
          </surface>
          <max_contacts>10</max_contacts>
        </collision>
        <collision name='pinky_link3_fixed_joint_lump__pinky_link_tip_collision_1'>
          <pose frame=''>0 0 0.0267 0 -0 0</pose>
          <geometry>
            <sphere>
              <radius>0.012</radius>
            </sphere>
          </geometry>
          <surface>
            <contact>
              <ode/>
            </contact>
            <friction>
              <ode/>
              <torsional>
                <ode/>
              </torsional>
            </friction>
            <bounce/>
          </surface>
          <max_contacts>10</max_contacts>
        </collision>
        <visual name='pinky_link3_visual'>
          <pose frame=''>0 0 0 0 -0 0</pose>
          <geometry>
            <mesh>
              <scale>1 1 1</scale>
              <uri>/home/work/code_repository/ros_packages/src/allegro_right_hand_description/model/meshes/link_3.0.STL</uri>
            </mesh>
          </geometry>
          <material>
            <script>
              <name>Gazebo/White</name>
              <uri>file://media/materials/scripts/gazebo.material</uri>
            </script>
          </material>
        </visual>
        <visual name='pinky_link3_fixed_joint_lump__pinky_link_tip_visual_1'>
          <pose frame=''>0 0 0.0267 0 -0 0</pose>
          <geometry>
            <mesh>
              <scale>1 1 1</scale>
              <uri>/home/work/code_repository/ros_packages/src/allegro_right_hand_description/model/meshes/link_3.0_tip.STL</uri>
            </mesh>
          </geometry>
          <material>
            <script>
              <name>Gazebo/White</name>
              <uri>file://media/materials/scripts/gazebo.material</uri>
            </script>
          </material>
        </visual>
        <velocity_decay/>
        <gravity>1</gravity>
        <velocity_decay/>
        <self_collide>0</self_collide>
        <kinematic>0</kinematic>
      </link>
      <joint name='pinky_joint4' type='revolute'>
        <child>pinky_link3</child>
        <parent>pinky_link2</parent>
        <axis>
          <xyz>0 0.996195 0.087156</xyz>
          <limit>
            <lower>-0.227</lower>
            <upper>1.618</upper>
            <effort>15</effort>
            <velocity>7</velocity>
          </limit>
          <dynamics>
            <damping>1</damping>
            <friction>1</friction>
            <spring_reference>0</spring_reference>
            <spring_stiffness>0</spring_stiffness>
          </dynamics>
          <use_parent_model_frame>1</use_parent_model_frame>
        </axis>
      </joint>
      <link name='thumb_link0'>
        <pose frame=''>-0.0182 0.019333 0.049013 3.14159 -1.48353 1.5708</pose>
        <inertial>
          <pose frame=''>0 0 0 0 -0 0</pose>
          <mass>0.176</mass>
          <inertia>
            <ixx>0.001</ixx>
            <ixy>0.001</ixy>
            <ixz>0.001</ixz>
            <iyy>0.001</iyy>
            <iyz>0.001</iyz>
            <izz>0.001</izz>
          </inertia>
        </inertial>
        <collision name='thumb_link0_collision'>
          <pose frame=''>-0.0179 0.009 0.0145 0 -0 0</pose>
          <geometry>
            <box>
              <size>0.0358 0.034 0.0455</size>
            </box>
          </geometry>
          <surface>
            <contact>
              <ode/>
            </contact>
            <friction>
              <ode/>
              <torsional>
                <ode/>
              </torsional>
            </friction>
            <bounce/>
          </surface>
          <max_contacts>10</max_contacts>
        </collision>
        <visual name='thumb_link0_visual'>
          <pose frame=''>0 0 0 0 -0 0</pose>
          <geometry>
            <mesh>
              <scale>1 1 1</scale>
              <uri>/home/work/code_repository/ros_packages/src/allegro_right_hand_description/model/meshes/link_12.0_right.STL</uri>
            </mesh>
          </geometry>
          <material>
            <script>
              <name>Gazebo/Blue</name>
              <uri>file://media/materials/scripts/gazebo.material</uri>
            </script>
          </material>
        </visual>
        <gravity>1</gravity>
        <velocity_decay/>
        <self_collide>0</self_collide>
        <kinematic>0</kinematic>
      </link>
      <joint name='thumb_joint1' type='revolute'>
        <child>thumb_link0</child>
        <parent>palm_link</parent>
        <axis>
          <xyz>0 -0.087156 -0.996195</xyz>
          <limit>
            <lower>0.263</lower>
            <upper>1.396</upper>
            <effort>15</effort>
            <velocity>7</velocity>
          </limit>
          <dynamics>
            <damping>3</damping>
            <friction>10</friction>
            <spring_reference>0</spring_reference>
            <spring_stiffness>0</spring_stiffness>
          </dynamics>
          <use_parent_model_frame>1</use_parent_model_frame>
        </axis>
      </joint>
      <link name='thumb_link1'>
        <pose frame=''>-0.0132 0.056728 0.018638 3.14159 -1.48353 1.5708</pose>
        <inertial>
          <pose frame=''>0 0 0 0 -0 0</pose>
          <mass>0.119</mass>
          <inertia>
            <ixx>0.001</ixx>
            <ixy>0.001</ixy>
            <ixz>0.001</ixz>
            <iyy>0.001</iyy>
            <iyz>0.001</iyz>
            <izz>0.001</izz>
          </inertia>
        </inertial>
        <collision name='thumb_link1_collision'>
          <pose frame=''>0 0 0.00885 0 -0 0</pose>
          <geometry>
            <box>
              <size>0.0196 0.0275 0.0177</size>
            </box>
          </geometry>
          <surface>
            <contact>
              <ode/>
            </contact>
            <friction>
              <ode/>
              <torsional>
                <ode/>
              </torsional>
            </friction>
            <bounce/>
          </surface>
          <max_contacts>10</max_contacts>
        </collision>
        <visual name='thumb_link1_visual'>
          <pose frame=''>0 0 0 0 -0 0</pose>
          <geometry>
            <mesh>
              <scale>1 1 1</scale>
              <uri>/home/work/code_repository/ros_packages/src/allegro_right_hand_description/model/meshes/link_13.0.STL</uri>
            </mesh>
          </geometry>
          <material>
            <script>
              <name>Gazebo/Orange</name>
              <uri>file://media/materials/scripts/gazebo.material</uri>
            </script>
          </material>
        </visual>
        <gravity>1</gravity>
        <velocity_decay/>
        <self_collide>0</self_collide>
        <kinematic>0</kinematic>
      </link>
      <joint name='thumb_joint2' type='revolute'>
        <child>thumb_link1</child>
        <parent>thumb_link0</parent>
        <axis>
          <xyz>0 0.996195 -0.087156</xyz>
          <limit>
            <lower>-0.105</lower>
            <upper>1.163</upper>
            <effort>15</effort>
            <velocity>7</velocity>
          </limit>
          <dynamics>
            <damping>3</damping>
            <friction>5</friction>
            <spring_reference>0</spring_reference>
            <spring_stiffness>0</spring_stiffness>
          </dynamics>
          <use_parent_model_frame>1</use_parent_model_frame>
        </axis>
      </joint>
      <link name='thumb_link2'>
        <pose frame=''>-0.0132 0.074361 0.017096 3.14159 -1.48353 1.5708</pose>
        <inertial>
          <pose frame=''>0 0 0 0 -0 0</pose>
          <mass>0.1</mass>
          <inertia>
            <ixx>0.001</ixx>
            <ixy>0.001</ixy>
            <ixz>0.001</ixz>
            <iyy>0.001</iyy>
            <iyz>0.001</iyz>
            <izz>0.001</izz>
          </inertia>
        </inertial>
        <collision name='thumb_link2_collision'>
          <pose frame=''>0 0 0.0257 0 -0 0</pose>
          <geometry>
            <box>
              <size>0.0196 0.0275 0.0514</size>
            </box>
          </geometry>
          <surface>
            <contact>
              <ode/>
            </contact>
            <friction>
              <ode/>
              <torsional>
                <ode/>
              </torsional>
            </friction>
            <bounce/>
          </surface>
          <max_contacts>10</max_contacts>
        </collision>
        <visual name='thumb_link2_visual'>
          <pose frame=''>0 0 0 0 -0 0</pose>
          <geometry>
            <mesh>
              <scale>1 1 1</scale>
              <uri>/home/work/code_repository/ros_packages/src/allegro_right_hand_description/model/meshes/link_14.0.STL</uri>
            </mesh>
          </geometry>
          <material>
            <script>
              <name>Gazebo/Red</name>
              <uri>file://media/materials/scripts/gazebo.material</uri>
            </script>
          </material>
        </visual>
        <gravity>1</gravity>
        <velocity_decay/>
        <self_collide>0</self_collide>
        <kinematic>0</kinematic>
      </link>
      <joint name='thumb_joint3' type='revolute'>
        <child>thumb_link2</child>
        <parent>thumb_link1</parent>
        <axis>
          <xyz>1 0 0</xyz>
          <limit>
            <lower>-0.189</lower>
            <upper>1.644</upper>
            <effort>15</effort>
            <velocity>7</velocity>
          </limit>
          <dynamics>
            <damping>3</damping>
            <friction>10</friction>
            <spring_reference>0</spring_reference>
            <spring_stiffness>0</spring_stiffness>
          </dynamics>
          <use_parent_model_frame>1</use_parent_model_frame>
        </axis>
      </joint>
      <link name='thumb_link3'>
        <pose frame=''>-0.0132 0.125565 0.012616 3.14159 -1.48353 1.5708</pose>
        <inertial>
          <pose frame=''>0 0 0.02115 0 -0 0</pose>
          <mass>0.2</mass>
          <inertia>
            <ixx>0.00208946</ixx>
            <ixy>0.002</ixy>
            <ixz>0.002</ixz>
            <iyy>0.00208946</iyy>
            <iyz>0.002</iyz>
            <izz>0.002</izz>
          </inertia>
        </inertial>
        <collision name='thumb_link3_collision'>
          <pose frame=''>0 0 0.02115 0 -0 0</pose>
          <geometry>
            <box>
              <size>0.0196 0.0275 0.0423</size>
            </box>
          </geometry>
          <surface>
            <contact>
              <ode/>
            </contact>
            <friction>
              <ode/>
              <torsional>
                <ode/>
              </torsional>
            </friction>
            <bounce/>
          </surface>
          <max_contacts>10</max_contacts>
        </collision>
        <collision name='thumb_link3_fixed_joint_lump__thumb_link_tip_collision_1'>
          <pose frame=''>0 0 0.0423 0 -0 0</pose>
          <geometry>
            <sphere>
              <radius>0.012</radius>
            </sphere>
          </geometry>
          <surface>
            <contact>
              <ode/>
            </contact>
            <friction>
              <ode/>
              <torsional>
                <ode/>
              </torsional>
            </friction>
            <bounce/>
          </surface>
          <max_contacts>10</max_contacts>
        </collision>
        <visual name='thumb_link3_visual'>
          <pose frame=''>0 0 0 0 -0 0</pose>
          <geometry>
            <mesh>
              <scale>1 1 1</scale>
              <uri>/home/work/code_repository/ros_packages/src/allegro_right_hand_description/model/meshes/link_15.0.STL</uri>
            </mesh>
          </geometry>
          <material>
            <script>
              <name>Gazebo/White</name>
              <uri>file://media/materials/scripts/gazebo.material</uri>
            </script>
          </material>
        </visual>
        <visual name='thumb_link3_fixed_joint_lump__thumb_link_tip_visual_1'>
          <pose frame=''>0 0 0.0423 0 -0 0</pose>
          <geometry>
            <mesh>
              <scale>1 1 1</scale>
              <uri>/home/work/code_repository/ros_packages/src/allegro_right_hand_description/model/meshes/link_15.0_tip.STL</uri>
            </mesh>
          </geometry>
          <material>
            <script>
              <name>Gazebo/White</name>
              <uri>file://media/materials/scripts/gazebo.material</uri>
            </script>
          </material>
        </visual>
        <velocity_decay/>
        <gravity>1</gravity>
        <velocity_decay/>
        <self_collide>0</self_collide>
        <kinematic>0</kinematic>
      </link>
      <joint name='thumb_joint4' type='revolute'>
        <child>thumb_link3</child>
        <parent>thumb_link2</parent>
        <axis>
          <xyz>1 0 0</xyz>
          <limit>
            <lower>-0.162</lower>
            <upper>1.719</upper>
            <effort>15</effort>
            <velocity>7</velocity>
          </limit>
          <dynamics>
            <damping>3</damping>
            <friction>12</friction>
            <spring_reference>0</spring_reference>
            <spring_stiffness>0</spring_stiffness>
          </dynamics>
          <use_parent_model_frame>1</use_parent_model_frame>
        </axis>
      </joint>
      <static>0</static>
      <plugin name='allegro_right_hand_control_plugin' filename='liballegro_right_hand_control_plugin.so'>
        <index_joint1_init>0.40</index_joint1_init>
        <index_joint2_init>0.50</index_joint2_init>
        <index_joint3_init>0.70</index_joint3_init>
        <index_joint4_init>0.70</index_joint4_init>
        <middle_joint1_init>0.00</middle_joint1_init>
        <middle_joint2_init>0.00</middle_joint2_init>
        <middle_joint3_init>0.00</middle_joint3_init>
        <middle_joint4_init>0.00</middle_joint4_init>
        <pinky_joint1_init>0.00</pinky_joint1_init>
        <pinky_joint2_init>0.00</pinky_joint2_init>
        <pinky_joint3_init>0.00</pinky_joint3_init>
        <pinky_joint4_init>0.00</pinky_joint4_init>
        <thumb_joint1_init>0.70</thumb_joint1_init>
        <thumb_joint2_init>0.20</thumb_joint2_init>
        <thumb_joint3_init>0.70</thumb_joint3_init>
        <thumb_joint4_init>0.70</thumb_joint4_init>
        <robotNamespace>/</robotNamespace>
      </plugin>
      <pose frame=''>0 0 0 0 -0 0</pose>
    </model>
    <state world_name='default'>
      <sim_time>0 434000000</sim_time>
      <real_time>0 574214226</real_time>
      <wall_time>1532998391 17435846</wall_time>
      <iterations>434</iterations>
      <model name='allegro_right_hand'>
        <pose frame=''>0 0 0 0 -0 0</pose>
        <scale>1 1 1</scale>
        <link name='index_link0'>
          <pose frame=''>0 0.0435 0.093458 -0.080409 0.033947 0.398634</pose>
          <velocity>0 0 0 0 -0 0</velocity>
          <acceleration>1e-06 -1e-06 0.000145 0.000621 -0.001168 0.001351</acceleration>
          <wrench>0 0 1.7e-05 0 -0 0</wrench>
        </link>
        <link name='index_link1'>
          <pose frame=''>0 0.044929 0.109796 -0.093294 0.532149 0.353931</pose>
          <velocity>0 0 0 0 -0 0</velocity>
          <acceleration>1e-06 -1e-06 0.000144 1.7e-05 -6e-06 7e-06</acceleration>
          <wrench>0 0 2.9e-05 0 -0 0</wrench>
        </link>
        <link name='index_link2'>
          <pose frame=''>0.023845 0.059103 0.156126 -0.239082 1.22496 0.175954</pose>
          <velocity>0 0 0 0 -0 0</velocity>
          <acceleration>1e-06 -1e-06 0.000137 2.31142 0.142718 0.285437</acceleration>
          <wrench>0 0 2.1e-05 0 -0 0</wrench>
        </link>
        <link name='index_link3'>
          <pose frame=''>0.05681 0.0742 0.168773 -2.9185 1.19963 -2.53187</pose>
          <velocity>0 0 0 0.000444 -0.001046 9.1e-05</velocity>
          <acceleration>3e-06 -4e-06 0.000135 0.91969 0.183874 2.36114</acceleration>
          <wrench>1e-06 -1e-06 2.7e-05 0 -0 0</wrench>
        </link>
        <link name='middle_link0'>
          <pose frame=''>0 0 0.0957 0 -0 0</pose>
          <velocity>0 0 0 0 -0 0</velocity>
          <acceleration>0 0 0 0 -0 0</acceleration>
          <wrench>0 0 2e-05 0 -0 0</wrench>
        </link>
        <link name='middle_link1'>
          <pose frame=''>0 0 0.1121 0 -0 0</pose>
          <velocity>0 0 0 0 -0 0</velocity>
          <acceleration>1e-06 -1e-06 0.000169 5e-06 -0 5e-06</acceleration>
          <wrench>0 0 3.4e-05 0 -0 0</wrench>
        </link>
        <link name='middle_link2'>
          <pose frame=''>0 0 0.1661 0 -0 0</pose>
          <velocity>0 0 0 0 -0 0</velocity>
          <acceleration>1e-06 -2e-06 0.000162 -0.000224 -0.000219 5e-06</acceleration>
          <wrench>0 0 2.4e-05 0 -0 0</wrench>
        </link>
        <link name='middle_link3'>
          <pose frame=''>0 0 0.2045 0 -0 0</pose>
          <velocity>0 0 0 0 -0 0</velocity>
          <acceleration>2e-06 -2e-06 0.000172 -3e-06 2e-06 0</acceleration>
          <wrench>0 0 3.4e-05 0 -0 0</wrench>
        </link>
        <link name='palm_link'>
          <pose frame=''>0 0 0.095 0 -0 0</pose>
          <velocity>0 0 0 0 -0 0</velocity>
          <acceleration>0 0 0 0 -0 0</acceleration>
          <wrench>0 0 0.000122 0 -0 0</wrench>
        </link>
        <link name='pinky_link0'>
          <pose frame=''>0 -0.0435 0.093458 0.087267 -0 0</pose>
          <velocity>0 0 0 0 -0 0</velocity>
          <acceleration>1e-06 -1e-06 0.0002 -8e-06 3e-05 2e-06</acceleration>
          <wrench>0 0 2.4e-05 0 -0 0</wrench>
        </link>
        <link name='pinky_link1'>
          <pose frame=''>0 -0.044929 0.109796 0.087267 -0 0</pose>
          <velocity>0 0 0 0 -0 0</velocity>
          <acceleration>1e-06 -1e-06 0.000198 1.5e-05 1.6e-05 8e-06</acceleration>
          <wrench>0 0 4e-05 0 -0 0</wrench>
        </link>
        <link name='pinky_link2'>
          <pose frame=''>0 -0.049636 0.16359 0.087267 -0 0</pose>
          <velocity>0 0 0 0 -0 0</velocity>
          <acceleration>2e-06 -2e-06 0.000192 0.024191 -0.025308 0.001097</acceleration>
          <wrench>0 0 2.9e-05 0 -0 0</wrench>
        </link>
        <link name='pinky_link3'>
          <pose frame=''>0 -0.052983 0.201844 0.087267 1e-05 1e-06</pose>
          <velocity>0 0 0 0 2.3e-05 2e-06</velocity>
          <acceleration>2e-06 -2e-06 0.000202 0.637525 1.3654 -1.64044</acceleration>
          <wrench>0 0 4e-05 0 -0 0</wrench>
        </link>
        <link name='thumb_link0'>
          <pose frame=''>-0.0182 0.019333 0.049013 2.44159 -1.48353 1.5708</pose>
          <velocity>0 0 0 0 -0 0</velocity>
          <acceleration>0 0 0 0 -0 0</acceleration>
          <wrench>0 0 5.2e-05 0 -0 0</wrench>
        </link>
        <link name='thumb_link1'>
          <pose frame=''>0.011329 0.044172 0.019737 -2.00731 -1.41247 -0.270166</pose>
          <velocity>0 0 0 0 -0 0</velocity>
          <acceleration>1e-06 0 0.00028 5e-06 -0.002301 -0.000287</acceleration>
          <wrench>0 0 3.3e-05 0 -0 0</wrench>
        </link>
        <link name='thumb_link2'>
          <pose frame=''>0.022731 0.057658 0.018557 -0.239487 -0.924333 -2.08983</pose>
          <velocity>0 0 0 0 -0 0</velocity>
          <acceleration>0 0 0 0 -0 0</acceleration>
          <wrench>0 0 2.4e-05 0 -0 0</wrench>
        </link>
        <link name='thumb_link3'>
          <pose frame=''>0.053089 0.086219 0.048635 -0.147482 -0.235681 -2.24765</pose>
          <velocity>0 0 0 4.7e-05 -4.1e-05 -9e-06</velocity>
          <acceleration>-1e-06 0 0.000183 -0.888093 -1.54862 0.657239</acceleration>
          <wrench>0 0 3.7e-05 0 -0 0</wrench>
        </link>
      </model>
      <light name='sun'>
        <pose frame=''>0 0 10 0 -0 0</pose>
      </light>
    </state>
    <gui fullscreen='0'>
      <camera name='user_camera'>
        <pose frame=''>0.211328 -0.085324 0.232309 0 0.543643 2.52819</pose>
        <view_controller>orbit</view_controller>
        <projection_type>perspective</projection_type>
      </camera>
    </gui>
  </world>
</sdf>
