<?xml version='1.0' encoding='utf-8'?>
<robot xmlns:xacro="http://www.ros.org/wiki/xacro" name="panda_arm">

<!-- robot constants -->
<xacro:property name="mass" value="1" /> <!-- arbitrary value for mass -->

<xacro:macro name="panda_arm" params="arm_id:='' description_pkg:='franka_panda_arm_description' connected_to:='' xyz:='0 0 0' rpy:='0 0 0'">

<xacro:unless value="${connected_to == ''}">
	<joint name="${arm_id}_joint_${connected_to}" type="fixed">
		<parent link="${connected_to}"/>
		<child link="${arm_id}_link0"/>
		<origin rpy="${rpy}" xyz="${xyz}"/>
	</joint>
</xacro:unless>

<!-- Used for fixing robot to Gazebo ground in case the robot is not connected to any other component -->
<xacro:if value="${connected_to == ''}">
	<link name="world"/>
	<joint name="fix_to_world" type="fixed">
		<parent link="world"/>
		<child link="${arm_id}_link0"/>
		<origin xyz="${xyz}" rpy="${rpy}"/>
	</joint>
</xacro:if>

<!-- Base Link (Link 0) -->
<link name="${arm_id}_link0">
	<visual>
		<geometry>
		<mesh filename="package://${description_pkg}/model/meshes/visual/link0.dae"/>
		</geometry>
	</visual>
	<collision>
		<geometry>
		<mesh filename="package://${description_pkg}/model/meshes/collision/link0.stl"/>
		</geometry>
	</collision>
	<inertial>
		<origin xyz="0 0 ${1/2}" rpy="0 0 0"/>
		<mass value="2.0"/>
		<inertia ixx="0.0" ixy="0.0" ixz="0.0" iyy="0.0" iyz="0.0" izz="0.0"/>
	</inertial>
</link>

<!-- Link 1 -->
<link name="${arm_id}_link1">
	<visual>
		<geometry>
		<mesh filename="package://${description_pkg}/model/meshes/visual/link1.dae"/>
		</geometry>
	</visual>
	<collision>
		<geometry>
		<mesh filename="package://${description_pkg}/model/meshes/collision/link1.stl"/>
		</geometry>
	</collision>
	<inertial>
		<origin xyz="0 0 -0.015" rpy="0 0 0"/>
		<mass value="2.7"/>
		<inertia ixx="0.006" ixy="0.0" ixz="0.0" iyy="0.006" iyz="0.0" izz="0.0015"/>
	</inertial>
</link>

<!-- Joint 1 -->
<joint name="${arm_id}_joint1" type="revolute">
	<safety_controller k_position="100.0" k_velocity="40.0" soft_lower_limit="-2.8973" soft_upper_limit="2.8973"/>
	<origin rpy="0 0 0" xyz="0 0 0.333"/>
	<parent link="${arm_id}_link0"/>
	<child link="${arm_id}_link1"/>
	<axis xyz="0 0 1"/>
	<dynamics damping="5.0" friction="1.5"/>
	<!-- <limit effort="87" lower="-2.9671" upper="2.9671" velocity="2.3925"/>  -->
	<limit effort="120" lower="-2.9671" upper="2.9671" velocity="2.3925"/>
</joint>

<!-- Link 2 -->
<link name="${arm_id}_link2">
	<visual>
		<geometry>
		<mesh filename="package://${description_pkg}/model/meshes/visual/link2.dae"/>
		</geometry>
	</visual>
	
	<collision>
		<geometry>
		<mesh filename="package://${description_pkg}/model/meshes/collision/link2.stl"/>
		</geometry>
	</collision>
	
	<inertial>
		<origin xyz="0 0 0.015" rpy="0 0 0"/>
		<mass value="2.7"/>
		<inertia ixx="0.006" ixy="0.0" ixz="0.0" iyy="0.006" iyz="0.0" izz="0.0015"/>
	</inertial>
</link>

<!-- Joint 2 -->
<joint name="${arm_id}_joint2" type="revolute">
	<safety_controller k_position="100.0" k_velocity="40.0" soft_lower_limit="-1.7628" soft_upper_limit="1.7628"/>
	<origin rpy="${-pi/2} 0 0" xyz="0 0 0"/>
	<parent link="${arm_id}_link1"/>
	<child link="${arm_id}_link2"/>
	<axis xyz="0 0 1"/>
	<dynamics damping="10.0" friction="1.5"/>
	<!-- <limit effort="87" lower="-1.8326" upper="1.8326" velocity="2.3925"/>  -->
	<limit effort="120" lower="-1.8326" upper="1.8326" velocity="2.3925"/>
</joint>

<!-- Link 3 -->
<link name="${arm_id}_link3">
	<visual>
		<geometry>
		<mesh filename="package://${description_pkg}/model/meshes/visual/link3.dae"/>
		</geometry>
	</visual>
	
	<collision>
		<geometry>
		<mesh filename="package://${description_pkg}/model/meshes/collision/link3.stl"/>
		</geometry>
	</collision>
	
	<inertial>
		<origin xyz="0 0 -0.015" rpy="0 0 0"/>
		<mass value="2.7"/>
		<inertia ixx="0.006" ixy="0.0" ixz="0.0" iyy="0.006" iyz="0.0015" izz="0.05"/>
	</inertial>
</link>

<!-- Joint 3 -->
<joint name="${arm_id}_joint3" type="revolute">
	<safety_controller k_position="100.0" k_velocity="40.0" soft_lower_limit="-2.8973" soft_upper_limit="2.8973"/>
	<origin rpy="${pi/2} 0 0" xyz="0 -0.316 0"/>
	<parent link="${arm_id}_link2"/>
	<child link="${arm_id}_link3"/>
	<axis xyz="0 0 1"/>
	<dynamics damping="5.0" friction="0.5"/>
	<!-- <limit effort="87" lower="-2.9671" upper="2.9671" velocity="2.3925"/>  -->
	<limit effort="120" lower="-2.9671" upper="2.9671" velocity="2.3925"/>
</joint>

<!-- Link 4 -->
<link name="${arm_id}_link4">
	<visual>
		<geometry>
		<mesh filename="package://${description_pkg}/model/meshes/visual/link4.dae"/>
		</geometry>
	</visual>
	
	<collision>
		<geometry>
		<mesh filename="package://${description_pkg}/model/meshes/collision/link4.stl"/>
		</geometry>
	</collision>
	
	<inertial>
		<origin xyz="0 0 0.015" rpy="0 0 0"/>
		<mass value="2.7"/>
		<inertia ixx="0.006" ixy="0.0" ixz="0.0" iyy="0.006" iyz="0.0" izz="0.0015"/>
	</inertial>
</link>

<!-- Joint 4 -->
<joint name="${arm_id}_joint4" type="revolute">
	<safety_controller k_position="100.0" k_velocity="40.0" soft_lower_limit="-3.0718" soft_upper_limit="0.0175"/>
	<origin rpy="${pi/2} 0 0" xyz="0.0825 0 0"/>
	<parent link="${arm_id}_link3"/>
	<child link="${arm_id}_link4"/>
	<axis xyz="0 0 1"/>
	<dynamics damping="5.0" friction="0.5"/>
	<!-- <limit effort="87" lower="-3.1416" upper="0.0873" velocity="2.3925"/>  -->
	<limit effort="120" lower="-3.1416" upper="0.0873" velocity="2.3925"/>
</joint>

<!-- Link 5 -->
<link name="${arm_id}_link5">
	<visual>
		<geometry>
		<mesh filename="package://${description_pkg}/model/meshes/visual/link5.dae"/>
		</geometry>
	</visual>
	
	<collision>
		<geometry>
		<mesh filename="package://${description_pkg}/model/meshes/collision/link5.stl"/>
		</geometry>
	</collision>
	
	<inertial>
		<origin xyz="0 0 -0.035" rpy="0 0 0"/>
		<mass value="1.7"/>
		<inertia ixx="0.006" ixy="0.0" ixz="0.0" iyy="0.006" iyz="0.0" izz="0.0014"/>
	</inertial>
</link>

<!-- Joint 5 -->
<joint name="${arm_id}_joint5" type="revolute">
	<safety_controller k_position="100.0" k_velocity="40.0" soft_lower_limit="-2.8973" soft_upper_limit="2.8973"/>
	<origin rpy="${-pi/2} 0 0" xyz="-0.0825 0.384 0"/>
	<parent link="${arm_id}_link4"/>
	<child link="${arm_id}_link5"/>
	<axis xyz="0 0 1"/>
	<dynamics damping="5.0" friction="1.5"/>
	<!-- <limit effort="12" lower="-2.9671" upper="2.9671" velocity="2.8710"/>  -->
	<limit effort="50" lower="-2.9671" upper="2.9671" velocity="2.8710"/>
</joint>

<!-- Link 6 -->
<link name="${arm_id}_link6">
	<visual>
		<geometry>
		<mesh filename="package://${description_pkg}/model/meshes/visual/link6.dae"/>
		</geometry>
	</visual>
	
	<collision>
		<geometry>
		<mesh filename="package://${description_pkg}/model/meshes/collision/link6.stl"/>
		</geometry>
	</collision>
	
	<inertial>
		<origin xyz="0 -0.008 0.001" rpy="0 0 0"/>
		<mass value="1.6"/>
		<inertia ixx="0.0018" ixy="0.0" ixz="0.0" iyy="0.0018" iyz="0.0" izz="0.0023"/>
	</inertial>
</link>

<!-- Joint 6 -->
<joint name="${arm_id}_joint6" type="revolute">
	<safety_controller k_position="100.0" k_velocity="40.0" soft_lower_limit="-0.0175" soft_upper_limit="3.7525"/>
	<origin rpy="${pi/2} 0 0" xyz="0 0 0"/>
	<parent link="${arm_id}_link5"/>
	<child link="${arm_id}_link6"/>
	<axis xyz="0 0 1"/>
	<dynamics damping="5.0" friction="1.5"/>
	<!-- <limit effort="12" lower="-0.0873" upper="3.8223" velocity="2.8710"/>  -->
	<limit effort="50" lower="-0.0873" upper="3.8223" velocity="2.8710"/>
</joint>

<!-- Link 7 -->
<link name="${arm_id}_link7">
	<visual>
		<geometry>
		<mesh filename="package://${description_pkg}/model/meshes/visual/link7.dae"/>
		</geometry>
	</visual>
	
	<collision>
		<geometry>
		<mesh filename="package://${description_pkg}/model/meshes/collision/link7.stl"/>
		</geometry>
	</collision>
	
	<inertial>
		<origin xyz="0 0 0.1" rpy="0 0 0"/>
		<mass value="1.0"/>
		<inertia ixx="0.05" ixy="0.0" ixz="0.0" iyy="0.05" iyz="0.0" izz="0.05"/>
	</inertial>
</link>

<!-- Joint 7 -->
<joint name="${arm_id}_joint7" type="revolute">
	<safety_controller k_position="100.0" k_velocity="40.0" soft_lower_limit="-2.8973" soft_upper_limit="2.8973"/>
	<origin rpy="${pi/2} 0 0" xyz="0.088 0 0"/>
	<parent link="${arm_id}_link6"/>
	<child link="${arm_id}_link7"/>
	<axis xyz="0 0 1"/>
	<dynamics damping="3.0" friction="0.5"/>
	<!-- <limit effort="12" lower="-2.9671" upper="2.9671" velocity="2.8710"/>  -->
	<limit effort="50" lower="-2.9671" upper="2.9671" velocity="2.8710"/>
</joint>

<!-- Link 8 : End Effector Frame -->
<link name="${arm_id}_link8"/>	


<!-- Joint 8 : Dummy Joint (Fixed) -->
<joint name="${arm_id}_joint8" type="fixed">
	<origin rpy="0 0 0" xyz="0 0 0.107"/>
	<parent link="${arm_id}_link7"/>
	<child link="${arm_id}_link8"/>
	<axis xyz="0 0 0"/>
</joint>



<transmission name="${arm_id}_trans1">
  <type>transmission_interface/SimpleTransmission</type>
  <joint name="${arm_id}_joint1">
    <hardwareInterface>hardware_interface/EffortJointInterface</hardwareInterface>
  </joint>
  <actuator name="${arm_id}_motor1">
    <hardwareInterface>hardware_interface/EffortJointInterface</hardwareInterface>
    <mechanicalReduction>1</mechanicalReduction>
  </actuator>
</transmission>

<transmission name="${arm_id}_trans2">
  <type>transmission_interface/SimpleTransmission</type>
  <joint name="${arm_id}_joint2">
    <hardwareInterface>hardware_interface/EffortJointInterface</hardwareInterface>
  </joint>
  <actuator name="${arm_id}_motor2">
    <hardwareInterface>hardware_interface/EffortJointInterface</hardwareInterface>
    <mechanicalReduction>1</mechanicalReduction>
  </actuator>
</transmission>

<transmission name="${arm_id}_trans3">
  <type>transmission_interface/SimpleTransmission</type>
  <joint name="${arm_id}_joint3">
    <hardwareInterface>hardware_interface/EffortJointInterface</hardwareInterface>
  </joint>
  <actuator name="${arm_id}_motor3">
    <hardwareInterface>hardware_interface/EffortJointInterface</hardwareInterface>
    <mechanicalReduction>1</mechanicalReduction>
  </actuator>
</transmission>

<transmission name="${arm_id}_trans4">
  <type>transmission_interface/SimpleTransmission</type>
  <joint name="${arm_id}_joint4">
    <hardwareInterface>hardware_interface/EffortJointInterface</hardwareInterface>
  </joint>
  <actuator name="${arm_id}_motor4">
    <hardwareInterface>hardware_interface/EffortJointInterface</hardwareInterface>
    <mechanicalReduction>1</mechanicalReduction>
  </actuator>
</transmission>

<transmission name="${arm_id}_trans5">
  <type>transmission_interface/SimpleTransmission</type>
  <joint name="${arm_id}_joint5">
    <hardwareInterface>hardware_interface/EffortJointInterface</hardwareInterface>
  </joint>
  <actuator name="${arm_id}_motor5">
    <hardwareInterface>hardware_interface/EffortJointInterface</hardwareInterface>
    <mechanicalReduction>1</mechanicalReduction>
  </actuator>
</transmission>

<transmission name="${arm_id}_trans6">
  <type>transmission_interface/SimpleTransmission</type>
  <joint name="${arm_id}_joint6">
    <hardwareInterface>hardware_interface/EffortJointInterface</hardwareInterface>
  </joint>
  <actuator name="${arm_id}_motor6">
    <hardwareInterface>hardware_interface/EffortJointInterface</hardwareInterface>
    <mechanicalReduction>1</mechanicalReduction>
  </actuator>
</transmission>

<transmission name="${arm_id}_trans7">
  <type>transmission_interface/SimpleTransmission</type>
  <joint name="${arm_id}_joint7">
    <hardwareInterface>hardware_interface/EffortJointInterface</hardwareInterface>
  </joint>
  <actuator name="${arm_id}_motor7">
    <hardwareInterface>hardware_interface/EffortJointInterface</hardwareInterface>
    <mechanicalReduction>1</mechanicalReduction>
  </actuator>
</transmission>



</xacro:macro>
</robot>

